Workbook

Sheet Maj26 - wydatki
A1: \
B2: Koszty stałe Damian | H2: Koszty stałe Malwina | N2: Kolumna nr 1 | O2: Wypłaty | P2: Suma | Q2: Koszty stałe | R2: Koszty dyn. | S2: Pozostałe | T2: Podsumowanie
C3: Rodzaj | D3: Budżet | E3: Pozostało | F3: Wydano | I3: Rodzaj | J3: Budżet | K3: Pozostało | L3: Wydano | N3: Damian | O3: 7260 | P3: =Q3+R3+S3 -> 6093 | Q3: =D14 -> 3675 | R3: =D21 -> 775 | S3: =D35 -> 1643 | T3: =O3-P3 -> 1167
B4: 2 | C4: internet | D4: 85 | E4: ='Maj26 - wydatki'!$D4-'Maj26 - wydatki'!$F4 -> 0 | F4: 85 | H4: 1 | I4: rata | J4: 3400 | N4: Malwina | O4: =5834+2300 -> 8134 | P4: =Q4+R4+S4 -> 9301 | Q4: =J17 -> 6065 | R4: =J29 -> 2583 | S4: =J41 -> 653 | T4: =O4-P4 -> -1167
B5: 4 | C5: telefon | D5: 40 | E5: ='Maj26 - wydatki'!$D5-'Maj26 - wydatki'!$F5 -> 40 | H5: 3 | I5: woda | J5: 160 | N5: Suma | O5: =K43=O3+O4 -> TRUE | P5: =Q5+R5+S5 -> 15394 | Q5: =Q3+Q4 -> 9740 | R5: =R3+R4 -> 3358 | S5: =S3+S4 -> 2296
B6: 7 | C6: paliwo | D6: 800 | E6: ='Maj26 - wydatki'!$D6-'Maj26 - wydatki'!$F6 -> 619 | F6: =181 -> 181 | H6: 9 | I6: jedzenie | J6: 800
B7: 8 | C7: jedzenie | D7: 800 | E7: ='Maj26 - wydatki'!$D7-'Maj26 - wydatki'!$F7 -> 481.79 | F7: =124+65.56+83.26+27+8+10.39 -> 318.21 | H7: 11 | I7: smieci | J7: 140 | N7: Oszczędnościowe
B8: 5 | C8: Gaz | D8: 300 | E8: ='Maj26 - wydatki'!$D8-F8 -> 98 | F8: 202 | H8: 12 | I8: izba | J8: 65 | N8: PEKAO | O8: DOM | P8: =4230+261+318-1650+300-223+300-250+250+228+453+350-332-350+358-120+500-200+400-60-2400+400+2400+153-800 -> 4516 | Q8: po II
B9: 14 | C9: rozne | D9: 100 | E9: ='Maj26 - wydatki'!$D9-'Maj26 - wydatki'!$F9 -> 100 | H9: 13 | I9: lekarz | J9: 300 | O9: NEW CAR | P9: 5500 | Q9: po III
B10: 19 | C10: auto | D10: 500 | E10: ='Maj26 - wydatki'!$D10-'Maj26 - wydatki'!$F10 -> 0 | F10: 500 | H10: 17 | I10: chemia | J10: 50 | O10: GAZ | P10: 31 | Q10: po III
B11: 21 | C11: fryzjer | D11: 50 | E11: ='Maj26 - wydatki'!$D11-'Maj26 - wydatki'!$F11 -> 0 | F11: 50 | H11: 18 | I11: mieszkanie | J11: 100 | P11: =P8+P9+P10 -> 10047
B12: 26 | C12: auto new | D12: 500 | E12: ='Maj26 - wydatki'!$D12-'Maj26 - wydatki'!$F12 -> 500 | H12: 20 | I12: swieta | J12: 100 | O12: auto | P12: 60 | Q12: po III
B13: 27 | C13: Kieszkonkowe D | D13: 500 | E13: =D13-F13 -> 0 | F13: 500 | H13: 22 | I13: fryzjer | J13: 50
C14: RAZEM | D14: =SUM(D4:D13) -> 3675 | E14: =SUM(E4:E13) -> 1838.79 | H14: 23 | I14: koszty roczne | J14: 350 | N14: poduszka mbank | P14: 3000 | Q14: po V
H15: 25 | I15: konkursy | J15: 50
B16: Koszty dynamiczne Damian | H16: 28 | I16: Kieszkonkowe M | J16: 500
C17: Rodzaj | D17: Budżet | E17: Pozostało | F17: Wydano | I17: RAZEM | J17: =SUM(J4:J16) -> 6065 | K17: =SUM(K4:K16) -> 0 | L17: =SUM(L4:L16) -> 0 | O17: =5310-206+19+83+36 -> 5242 | Q17: =68-52 -> 16
C18: Poduszka finansowa | D18: 500 | E18: ='Maj26 - wydatki'!$D18-F18 -> 0 | F18: 500
C19: Dom | D19: 275 | E19: ='Maj26 - wydatki'!$D19-F19 -> 275 | H19: Koszty dynamiczne Malwina
C20: Tv | E20: ='Maj26 - wydatki'!$D20-F20 -> 0 | I20: Rodzaj | J20: Budżet | K20: Pozostało | L20: Wydano
C21: RAZEM | D21: =SUM(D18:D20) -> 775 | E21: =SUM(E18:E20) -> 275 | F21: =SUM(F18:F20) -> 500 | H21: 6 | I21: Przedszkole | J21: 1145
H22: 15 | I22: Dzieci | J22: 200
B23: Pozostałe Damian | H23: 16 | I23: Apteka | J23: 100
C24: Rodzaj | D24: Budżet | E24: Pozostało | F24: Wydano | I24: Urodziny dzieci | J24: 100
B25: 10 | C25: Woda | D25: 50 | E25: =D25-F25 -> 50 | I25: Maja lutcza | J25: 50
C26: splata auta | D26: 1500 | E26: =D26-F26 -> 1500 | H26: 21 | I26: Wakacje | J26: 400
C27: Ostrza | E27: =D27-F27 -> 0 | H27: 25 | I27: Zabawowe | J27: 488
B28: 23 | C28: Prąd | D28: 93 | E28: =D28-F28 -> 93 | H28: 31 | I28: Emerytura Rodziców | J28: 100
C29: Siłka | E29: =D29-F29 -> 0 | I29: RAZEM | J29: =SUM(J21:J28) -> 2583 | K29: =SUM(K21:K27) -> 0 | L29: =SUM(L21:L27) -> 0 | N29: jedzenie | O29: 124
C30: ladowarka | E30: =D30-F30 -> 0
C31: sylwek | E31: =D31-F31 -> 0 | H31: Pozostałe Malwina
C32: telefon | E32: =D32-F32 -> 0 | I32: Rodzaj | J32: Budżet | K32: Pozostało | L32: Wydano
B33: 30 | C33: Mateusz | E33: =D33-F33 -> 0 | H33: 22 | I33: Podatek | J33: 94
C34: youtube | E34: =D34-F34 -> 0 | I34: Czynsz Mieszkanie | J34: 350
C35: RAZEM | D35: =SUM(D25:D34) -> 1643 | E35: =SUM(E25:E34) -> 1643 | F35: =SUM(F25:F34) -> 0 | H35: 24 | I35: auto spłata | J35: 0
H36: 29 | I36: Telefon
C37: pozostało II | D37: =E35+E21+E14 -> 3756.79 | E37: =150 -> 150 | F37: Sylwek + tv | I37: uro | J37: 209
C38: pozostało XI | H38: 26 | I38: żel do mycia
C39: Total | E39: =E37+E38+D37 -> 3906.79 | I39: kawa praca
I40: pasta
...

Sheet Kwiecień26 - wydatki
A1: \
B2: Koszty stałe Damian | H2: Koszty stałe Malwina | N2: Kolumna nr 1 | O2: Wypłaty | P2: Suma | Q2: Koszty stałe | R2: Koszty dyn. | S2: Pozostałe | T2: Podsumowanie
C3: Rodzaj | D3: Budżet | E3: Pozostało | F3: Wydano | I3: Rodzaj | J3: Budżet | K3: Pozostało | L3: Wydano | N3: Damian | O3: 7660 | P3: =Q3+R3+S3 -> 5259 | Q3: =D14 -> 4075 | R3: =D21 -> 861 | S3: =D35 -> 323 | T3: =O3-P3 -> 2401
B4: 2 | C4: internet | D4: 85 | E4: ='Kwiecień26 - wydatki'!$D4-'Kwiecień26 - wydatki'!$F4 -> 0 | F4: 85 | H4: 1 | I4: rata | J4: 3400 | N4: Malwina | O4: =5832+2300 -> 8132 | P4: =Q4+R4+S4 -> 10533 | Q4: =J17 -> 6045 | R4: =J29 -> 2545 | S4: =J41 -> 1943 | T4: =O4-P4 -> -2401
B5: 4 | C5: telefon | D5: 40 | E5: ='Kwiecień26 - wydatki'!$D5-'Kwiecień26 - wydatki'!$F5 -> 0 | F5: 40 | H5: 3 | I5: woda | J5: 140 | N5: Suma | O5: =K43=O3+O4 -> TRUE | P5: =Q5+R5+S5 -> 15792 | Q5: =Q3+Q4 -> 10120 | R5: =R3+R4 -> 3406 | S5: =S3+S4 -> 2266
B6: 7 | C6: paliwo | D6: 1200 | E6: ='Kwiecień26 - wydatki'!$D6-'Kwiecień26 - wydatki'!$F6 -> -0.27 | F6: =8+155+280+285+250+10+143.27+69 -> 1200.27 | H6: 9 | I6: jedzenie | J6: 800
B7: 8 | C7: jedzenie | D7: 800 | E7: ='Kwiecień26 - wydatki'!$D7-'Kwiecień26 - wydatki'!$F7 -> -0.39 | F7: =75.71+13.55+190.8+8.29+14.48+38.3+5.4+14.32+25+44.37+57.33+16+10+106.38+35.95+57.97-50+74.39+6.99+28.08+3+43.34+9.79+46.05+0.79+66.11-18-124 -> 800.39 | H7: 11 | I7: smieci | J7: 140 | N7: Oszczędnościowe
B8: 5 | C8: Gaz | D8: 300 | E8: ='Kwiecień26 - wydatki'!$D8-F8 -> 0 | F8: =269+31 -> 300 | H8: 12 | I8: izba | J8: 65 | N8: PEKAO | O8: DOM | P8: =4230+261+318-1650+300-223+300-250+250+228+453+350-332-350+358-120+500-200+400-60-2400+400+2400+153 -> 5316 | Q8: po IV
B9: 14 | C9: rozne | D9: 100 | E9: ='Kwiecień26 - wydatki'!$D9-'Kwiecień26 - wydatki'!$F9 -> 0.01 | F9: =10+18+35+10+8.99+18 -> 99.99 | H9: 13 | I9: lekarz | J9: 300 | O9: NEW CAR | P9: 5500 | Q9: po IV
B10: 19 | C10: auto | D10: 500 | E10: ='Kwiecień26 - wydatki'!$D10-'Kwiecień26 - wydatki'!$F10 -> 0 | F10: =30+140+330 -> 500 | H10: 17 | I10: chemia | J10: 50 | O10: GAZ | P10: 31 | Q10: po IV
B11: 21 | C11: fryzjer | D11: 50 | E11: ='Kwiecień26 - wydatki'!$D11-'Kwiecień26 - wydatki'!$F11 -> 0 | F11: 50 | H11: 18 | I11: mieszkanie | J11: 100 | P11: =P8+P9+P10 -> 10847
B12: 26 | C12: auto new | D12: 500 | E12: ='Kwiecień26 - wydatki'!$D12-'Kwiecień26 - wydatki'!$F12 -> 0 | F12: 500 | H12: 20 | I12: swieta | J12: 100
B13: 27 | C13: Kieszkonkowe D | D13: 500 | E13: =D13-F13 -> 0 | F13: =62+30+94+314 -> 500 | H13: 22 | I13: fryzjer | J13: 50
C14: RAZEM | D14: =SUM(D4:D13) -> 4075 | E14: =SUM(E4:E13) -> -0.65 | H14: 23 | I14: koszty roczne | J14: 350 | N14: poduszka mbank | P14: 2000 | Q14: po III
H15: 25 | I15: konkursy | J15: 50
B16: Koszty dynamiczne Damian | H16: 28 | I16: Kieszkonkowe M | J16: 500
C17: Rodzaj | D17: Budżet | E17: Pozostało | F17: Wydano | I17: RAZEM | J17: =SUM(J4:J16) -> 6045 | K17: =SUM(K4:K16) -> 0 | L17: =SUM(L4:L16) -> 0
C18: Poduszka finansowa | D18: 500 | E18: ='Kwiecień26 - wydatki'!$D18-F18 -> 0 | F18: 500
C19: Dom | D19: 361 | E19: ='Kwiecień26 - wydatki'!$D19-F19 -> 0 | F19: =198+10+153 -> 361 | H19: Koszty dynamiczne Malwina
C20: Tv | E20: ='Kwiecień26 - wydatki'!$D20-F20 -> 0 | I20: Rodzaj | J20: Budżet | K20: Pozostało | L20: Wydano
C21: RAZEM | D21: =SUM(D18:D20) -> 861 | E21: =SUM(E18:E20) -> 0 | F21: =SUM(F18:F20) -> 861 | H21: 6 | I21: Przedszkole | J21: 1195
H22: 15 | I22: Dzieci | J22: 200
B23: Pozostałe Damian | H23: 16 | I23: Apteka | J23: 100
C24: Rodzaj | D24: Budżet | E24: Pozostało | F24: Wydano | I24: Urodziny dzieci | J24: 100
B25: 10 | C25: Woda | D25: 50 | E25: =D25-F25 -> 0 | F25: 50 | I25: Maja lutcza | J25: 50
C26: Mama Bukiet | D26: 180 | E26: =D26-F26 -> 0 | F26: 180 | H26: 21 | I26: Wakacje | J26: 400
C27: Ostrza | E27: =D27-F27 -> 0 | H27: 25 | I27: Zabawowe | J27: 400
B28: 23 | C28: Prąd | D28: 93 | E28: =D28-F28 -> 0 | F28: 93 | H28: 31 | I28: Emerytura Rodziców | J28: 100
C29: Siłka | E29: =D29-F29 -> 0 | I29: RAZEM | J29: =SUM(J21:J28) -> 2545 | K29: =SUM(K21:K27) -> 0 | L29: =SUM(L21:L27) -> 0
C30: ladowarka | E30: =D30-F30 -> 0
C31: sylwek | E31: =D31-F31 -> 0 | H31: Pozostałe Malwina
C32: telefon | E32: =D32-F32 -> 0 | I32: Rodzaj | J32: Budżet | K32: Pozostało | L32: Wydano
B33: 30 | C33: Mateusz | E33: =D33-F33 -> 0 | H33: 22 | I33: Podatek
C34: youtube | E34: =D34-F34 -> 0 | I34: Czynsz Mieszkanie | J34: 350
C35: RAZEM | D35: =SUM(D25:D34) -> 323 | E35: =SUM(E25:E34) -> 0 | F35: =SUM(F25:F34) -> 323 | H35: 24 | I35: auto spłata | J35: 1500
H36: 29 | I36: Telefon
C37: pozostało II | D37: =E35+E21+E14 -> -0.65 | E37: =150 -> 150 | F37: Sylwek + tv | I37: uro | J37: 93
C38: pozostało XI | H38: 26 | I38: żel do mycia
C39: Total | E39: =E37+E38+D37 -> 149.35 | I39: kawa praca
I40: pasta
...

Sheet Marzec26 - wydatki
A1: \
B2: Koszty stałe Damian | H2: Koszty stałe Malwina | N2: Kolumna nr 1 | O2: Wypłaty | P2: Suma | Q2: Koszty stałe | R2: Koszty dyn. | S2: Pozostałe | T2: Podsumowanie
C3: Rodzaj | D3: Budżet | E3: Pozostało | F3: Wydano | I3: Rodzaj | J3: Budżet | K3: Pozostało | L3: Wydano | N3: Damian | O3: 7260 | P3: =Q3+R3+S3 -> 6025 | Q3: =D14 -> 4685 | R3: =D21 -> 900 | S3: =D35 -> 440 | T3: =O3-P3 -> 1235
B4: 2 | C4: internet | D4: 85 | E4: ='Marzec26 - wydatki'!$D4-'Marzec26 - wydatki'!$F4 -> 0 | F4: 85 | H4: 1 | I4: rata | J4: 3400 | N4: Malwina | O4: =5786+2300 -> 8086 | P4: =Q4+R4+S4 -> 9321 | Q4: =J17 -> 6188 | R4: =J29 -> 2590 | S4: =J41 -> 543 | T4: =O4-P4 -> -1235
B5: 4 | C5: telefon | D5: 40 | E5: ='Marzec26 - wydatki'!$D5-'Marzec26 - wydatki'!$F5 -> 0 | F5: 40 | H5: 3 | I5: woda | J5: 283 | N5: Suma | O5: =K43=O3+O4 -> TRUE | P5: =Q5+R5+S5 -> 15346 | Q5: =Q3+Q4 -> 10873 | R5: =R3+R4 -> 3490 | S5: =S3+S4 -> 983
B6: 7 | C6: paliwo | D6: 800 | E6: ='Marzec26 - wydatki'!$D6-'Marzec26 - wydatki'!$F6 -> 0 | F6: =111+223+326+140 -> 800 | H6: 9 | I6: jedzenie | J6: 800
B7: 8 | C7: jedzenie | D7: 800 | E7: ='Marzec26 - wydatki'!$D7-'Marzec26 - wydatki'!$F7 -> 0.39 | F7: =18.52+57.24+72.31+14.78+9+9.47+29.2+10.38+16.16+20-10+78.33+42.55+8.47+20.97+32.57+26.68+35.59+18.41+50.19+211.01+4.23+13.55+10 -> 799.61 | H7: 11 | I7: smieci | J7: 140 | N7: Oszczędnościowe
B8: 5 | C8: Gaz | D8: 310 | E8: ='Marzec26 - wydatki'!$D8-F8 -> 0 | F8: 310 | H8: 12 | I8: izba | J8: 65 | N8: PEKAO | O8: DOM | P8: =4230+261+318-1650+300-223+300-250+250+228+453+350-332-350+358-120+500-200+400-60-2400+400 -> 2763 | Q8: po II
B9: 14 | C9: rozne | D9: 100 | E9: ='Marzec26 - wydatki'!$D9-'Marzec26 - wydatki'!$F9 -> 0 | F9: =5+15+30+67.5-17.5 -> 100 | H9: 13 | I9: lekarz | J9: 300 | O9: NEW CAR | P9: =6660+1230+100+10+1000+1000+1000+1000+1500+1500+1500-15000+1500 -> 3000 | Q9: po III
B10: 19 | C10: auto | D10: 500 | E10: ='Marzec26 - wydatki'!$D10-'Marzec26 - wydatki'!$F10 -> 0 | F10: 500 | H10: 17 | I10: chemia | J10: 50 | O10: GAZ | P10: =127+100+152+173+163+150+65-178-300-230-222 -> 0 | Q10: po III
B11: 21 | C11: fryzjer | D11: 50 | E11: ='Marzec26 - wydatki'!$D11-'Marzec26 - wydatki'!$F11 -> 0 | F11: 50 | H11: 18 | I11: mieszkanie | J11: 100 | P11: =P8+P9+P10 -> 5763
B12: 26 | C12: auto new | D12: 1500 | E12: ='Marzec26 - wydatki'!$D12-'Marzec26 - wydatki'!$F12 -> 0 | F12: 1500 | H12: 20 | I12: swieta | J12: 100 | O12: auto | P12: 500 | Q12: po XII
B13: 27 | C13: Kieszkonkowe D | D13: 500 | E13: =D13-F13 -> 0 | F13: =230+18+250+2 -> 500 | H13: 22 | I13: fryzjer | J13: 50
C14: RAZEM | D14: =SUM(D4:D13) -> 4685 | E14: =SUM(E4:E13) -> 0.39 | H14: 23 | I14: koszty roczne | J14: 350 | N14: poduszka mbank | P14: 2000 | Q14: po III
H15: 25 | I15: konkursy | J15: 50
B16: Koszty dynamiczne Damian | H16: 28 | I16: Kieszkonkowe M | J16: 500
C17: Rodzaj | D17: Budżet | E17: Pozostało | F17: Wydano | I17: RAZEM | J17: =SUM(J4:J16) -> 6188 | K17: =SUM(K4:K16) -> 0 | L17: =SUM(L4:L16) -> 0 | O17: =5310-206+19+83+36 -> 5242 | Q17: =68-52 -> 16
C18: Poduszka finansowa | D18: 500 | E18: ='Marzec26 - wydatki'!$D18-F18 -> 0 | F18: 500
C19: Dom | D19: 400 | E19: ='Marzec26 - wydatki'!$D19-F19 -> 0 | F19: 400 | H19: Koszty dynamiczne Malwina
C20: Tv | E20: ='Marzec26 - wydatki'!$D20-F20 -> 0 | I20: Rodzaj | J20: Budżet | K20: Pozostało | L20: Wydano
C21: RAZEM | D21: =SUM(D18:D20) -> 900 | E21: =SUM(E18:E20) -> 0 | F21: =SUM(F18:F20) -> 900 | H21: 6 | I21: Przedszkole | J21: 1178
H22: 15 | I22: Dzieci | J22: 200
B23: Pozostałe Damian | H23: 16 | I23: Apteka | J23: 100
C24: Rodzaj | D24: Budżet | E24: Pozostało | F24: Wydano | I24: Urodziny dzieci | J24: 100
B25: 10 | C25: Woda | D25: 50 | E25: =D25-F25 -> 0 | F25: =10+10+10+20 -> 50 | I25: Maja lutcza | J25: 50
C26: Mama Bukiet | E26: =D26-F26 -> 0 | H26: 21 | I26: Wakacje | J26: 400
C27: Ostrza | E27: =D27-F27 -> 0 | H27: 25 | I27: Zabawowe | J27: 462
B28: 23 | C28: Prąd | D28: 90 | E28: =D28-F28 -> 0 | F28: 90 | H28: 31 | I28: Emerytura Rodziców | J28: 100
C29: Siłka | D29: 300 | E29: =D29-F29 -> 0 | F29: 300 | I29: RAZEM | J29: =SUM(J21:J28) -> 2590 | K29: =SUM(K21:K27) -> 0 | L29: =SUM(L21:L27) -> 0
C30: ladowarka | E30: =D30-F30 -> 0
C31: sylwek | E31: =D31-F31 -> 0 | H31: Pozostałe Malwina
C32: telefon | E32: =D32-F32 -> 0 | I32: Rodzaj | J32: Budżet | K32: Pozostało | L32: Wydano
B33: 30 | C33: Mateusz | E33: =D33-F33 -> 0 | H33: 22 | I33: Podatek | J33: 94
C34: youtube | E34: =D34-F34 -> 0 | I34: Czynsz Mieszkanie | J34: 350
C35: RAZEM | D35: =SUM(D25:D34) -> 440 | E35: =SUM(E25:E34) -> 0 | F35: =SUM(F25:F34) -> 440 | H35: 24 | I35: Orawa Deca
H36: 29 | I36: Telefon
C37: pozostało II | D37: =E35+E21+E14 -> 0.39 | E37: =150 -> 150 | F37: Sylwek + tv | I37: uro | J37: 99
C38: pozostało XI | H38: 26 | I38: żel do mycia
C39: Total | E39: =E37+E38+D37 -> 150.39 | I39: kawa praca
I40: pasta
...

Sheet Luty26 - wydatki
A1: \
B2: Koszty stałe Damian | H2: Koszty stałe Malwina | N2: Kolumna nr 1 | O2: Wypłaty | P2: Suma | Q2: Koszty stałe | R2: Koszty dyn. | S2: Pozostałe | T2: Podsumowanie
C3: Rodzaj | D3: Budżet | E3: Pozostało | F3: Wydano | I3: Rodzaj | J3: Budżet | K3: Pozostało | L3: Wydano | N3: Damian | O3: 7025 | P3: =Q3+R3+S3 -> 6295 | Q3: =D14 -> 4975 | R3: =D21 -> 500 | S3: =D35 -> 820 | T3: =O3-P3 -> 730
B4: 2 | C4: internet | D4: 85 | E4: ='Luty26 - wydatki'!$D4-'Luty26 - wydatki'!$F4 -> 0 | F4: 85 | H4: 1 | I4: rata | J4: 3400 | N4: Malwina | O4: =7966+250 -> 8216 | P4: =Q4+R4+S4 -> 8946 | Q4: =J17 -> 6097 | R4: =J29 -> 1946 | S4: =J41 -> 903 | T4: =O4-P4 -> -730
B5: 4 | C5: telefon | D5: 40 | E5: ='Luty26 - wydatki'!$D5-'Luty26 - wydatki'!$F5 -> 0 | F5: 40 | H5: 3 | I5: woda | J5: 140 | N5: Suma | O5: =K43=O3+O4 -> TRUE | P5: =Q5+R5+S5 -> 15241 | Q5: =Q3+Q4 -> 11072 | R5: =R3+R4 -> 2446 | S5: =S3+S4 -> 1723
B6: 7 | C6: paliwo | D6: 800 | E6: ='Luty26 - wydatki'!$D6-'Luty26 - wydatki'!$F6 -> 0 | F6: =208+92+60+104+314+20+2 -> 800 | H6: 9 | I6: jedzenie | J6: 800
B7: 8 | C7: jedzenie | D7: 800 | E7: ='Luty26 - wydatki'!$D7-'Luty26 - wydatki'!$F7 -> 0 | F7: =196+8+4+16.93+22.77+13.48+77.39+7.65+1.1+9.75+68.35+3.4+33.92-20+54.74+34.58+26.87+209.8+36.01+31.61+37.56-74+0.09 -> 800 | H7: 11 | I7: smieci | J7: =140+52 -> 192 | N7: Oszczędnościowe
B8: 5 | C8: Gaz | D8: =350+250 -> 600 | E8: ='Luty26 - wydatki'!$D8-F8 -> 0 | F8: 600 | H8: 12 | I8: izba | J8: 65 | N8: PEKAO | O8: DOM | P8: =4230+261+318-1650+300-223+300-250+250+228+453+350-332-350+358-120+500-200+400-60-2400 -> 2363 | Q8: po II
B9: 14 | C9: rozne | D9: 100 | E9: ='Luty26 - wydatki'!$D9-'Luty26 - wydatki'!$F9 -> 0 | F9: =12+10+10+10+5+16+9+28 -> 100 | H9: 13 | I9: lekarz | J9: 300 | O9: NEW CAR | P9: =6660+1230+100+10+1000+1000+1000+1000+1500+1500+1500-15000 -> 1500 | Q9: po II
B10: 19 | C10: auto | D10: 500 | E10: ='Luty26 - wydatki'!$D10-'Luty26 - wydatki'!$F10 -> 0 | F10: 500 | H10: 17 | I10: chemia | J10: 50 | O10: GAZ | P10: =127+100+152+173+163+150+65-178-300-230 -> 222 | Q10: po I
B11: 21 | C11: fryzjer | D11: 50 | E11: ='Luty26 - wydatki'!$D11-'Luty26 - wydatki'!$F11 -> 0 | F11: 50 | H11: 18 | I11: mieszkanie | J11: 100 | P11: =P8+P9+P10 -> 4085
B12: 26 | C12: auto new | D12: 1500 | E12: ='Luty26 - wydatki'!$D12-'Luty26 - wydatki'!$F12 -> 0 | F12: 1500 | H12: 20 | I12: swieta | J12: 100 | O12: auto | P12: 500 | Q12: po XII
B13: 27 | C13: Kieszkonkowe D | D13: 500 | E13: =D13-F13 -> 0 | F13: =125+80+189+50+22+104+90-160 -> 500 | H13: 22 | I13: fryzjer | J13: 50
C14: RAZEM | D14: =SUM(D4:D13) -> 4975 | E14: =SUM(E4:E13) -> 0 | H14: 23 | I14: koszty roczne | J14: 350
H15: 25 | I15: konkursy | J15: 50
B16: Koszty dynamiczne Damian | H16: 28 | I16: Kieszkonkowe M | J16: 500
C17: Rodzaj | D17: Budżet | E17: Pozostało | F17: Wydano | I17: RAZEM | J17: =SUM(J4:J16) -> 6097 | K17: =SUM(K4:K16) -> 0 | L17: =SUM(L4:L16) -> 0 | O17: =5310-206+19+83+36 -> 5242 | Q17: =68-52 -> 16
C18: Poduszka finansowa | D18: 500 | E18: ='Luty26 - wydatki'!$D18-F18 -> 0 | F18: 500
C19: Dom | E19: ='Luty26 - wydatki'!$D19-F19 -> 0 | H19: Koszty dynamiczne Malwina
C20: Tv | E20: ='Luty26 - wydatki'!$D20-F20 -> 0 | I20: Rodzaj | J20: Budżet | K20: Pozostało | L20: Wydano
C21: RAZEM | D21: =SUM(D18:D20) -> 500 | E21: =SUM(E18:E20) -> 0 | F21: =SUM(F18:F20) -> 500 | H21: 6 | I21: Przedszkole | J21: 1096
H22: 15 | I22: Dzieci | J22: 200
B23: Pozostałe Damian | H23: 16 | I23: Apteka | J23: 100
C24: Rodzaj | D24: Budżet | E24: Pozostało | F24: Wydano | I24: Urodziny dzieci | J24: 100
B25: 10 | C25: Woda | D25: 50 | E25: =D25-F25 -> 0 | F25: =20+30 -> 50 | I25: Maja lutcza | J25: 50
C26: Mama Bukiet | E26: =D26-F26 -> 0 | H26: 21 | I26: Wakacje
C27: Ostrza | E27: =D27-F27 -> 0 | H27: 25 | I27: Zabawowe | J27: 300
B28: 23 | C28: Prąd | E28: =D28-F28 -> 0 | H28: 31 | I28: Emerytura Rodziców | J28: 100
C29: Siłka | D29: 300 | E29: =D29-F29 -> 0 | F29: 300 | I29: RAZEM | J29: =SUM(J21:J28) -> 1946 | K29: =SUM(K21:K27) -> 0 | L29: =SUM(L21:L27) -> 0
C30: ladowarka | E30: =D30-F30 -> 0
C31: sylwek | E31: =D31-F31 -> 0 | H31: Pozostałe Malwina
C32: telefon | D32: 400 | E32: =D32-F32 -> 400 | I32: Rodzaj | J32: Budżet | K32: Pozostało | L32: Wydano
B33: 30 | C33: Mateusz | D33: 70 | E33: =D33-F33 -> 0 | F33: 70 | H33: 22 | I33: Podatek | J33: 55
C34: youtube | E34: =D34-F34 -> 0 | I34: Czynsz Mieszkanie | J34: 350
C35: RAZEM | D35: =SUM(D25:D34) -> 820 | E35: =SUM(E25:E34) -> 400 | F35: =SUM(F25:F34) -> 420 | H35: 24 | I35: Orawa Deca | J35: 317
H36: 29 | I36: Telefon
C37: pozostało I | D37: =E35+E21+E14 -> 400 | E37: 150 | I37: allegro smart | J37: 59
C38: pozostało XI | H38: 26 | I38: żel do mycia | J38: 55
C39: Total | E39: =E37+E38+D37 -> 550 | I39: kawa praca | J39: 24
I40: pasta | J40: 43
...

Sheet Styczeń26 - wydatki
A1: \
B2: Koszty stałe Damian | H2: Koszty stałe Malwina | N2: Kolumna nr 1 | O2: Wypłaty | P2: Suma | Q2: Koszty stałe | R2: Koszty dyn. | S2: Pozostałe | T2: Podsumowanie
C3: Rodzaj | D3: Budżet | E3: Pozostało | F3: Wydano | I3: Rodzaj | J3: Budżet | K3: Pozostało | L3: Wydano | N3: Damian | O3: 7260 | P3: =Q3+R3+S3 -> 6204 | Q3: =D14 -> 4655 | R3: =D21 -> 900 | S3: =D35 -> 649 | T3: =O3-P3 -> 1056
B4: 2 | C4: internet | D4: 85 | E4: ='Styczeń26 - wydatki'!$D4-'Styczeń26 - wydatki'!$F4 -> 0 | F4: 85 | H4: 1 | I4: rata | J4: 3400 | N4: Malwina | O4: 7966 | P4: =Q4+R4+S4 -> 9022 | Q4: =J17 -> 6045 | R4: =J29 -> 2427 | S4: =J41 -> 550 | T4: =O4-P4 -> -1056
B5: 4 | C5: telefon | D5: 40 | E5: ='Styczeń26 - wydatki'!$D5-'Styczeń26 - wydatki'!$F5 -> 0 | F5: 40 | H5: 3 | I5: woda | J5: 140 | N5: Suma | O5: =K43=O3+O4 -> TRUE | P5: =Q5+R5+S5 -> 15226 | Q5: =Q3+Q4 -> 10700 | R5: =R3+R4 -> 3327 | S5: =S3+S4 -> 1199
B6: 7 | C6: paliwo | D6: 800 | E6: ='Styczeń26 - wydatki'!$D6-'Styczeń26 - wydatki'!$F6 -> 0 | F6: =200+200+337+63 -> 800 | H6: 9 | I6: jedzenie | J6: 800
B7: 8 | C7: jedzenie | D7: 800 | E7: ='Styczeń26 - wydatki'!$D7-'Styczeń26 - wydatki'!$F7 -> 0 | F7: =128+34.69+6.84+1.52+35.05+62.27+63.64+106.23+11.58+107.67+191.07+54.14+19.94+84.94+30.85-138.43 -> 800 | H7: 11 | I7: smieci | J7: 140 | N7: Oszczędnościowe
B8: 5 | C8: Gaz | D8: 300 | E8: ='Styczeń26 - wydatki'!$D8-F8 -> 0 | F8: 300 | H8: 12 | I8: izba | J8: 65 | N8: PEKAO | O8: DOM | P8: =4230+261+318-1650+300-223+300-250+250+228+453+350-332-350+358-120+500+400 -> 5023 | Q8: po I
B9: 14 | C9: rozne | D9: 80 | E9: ='Styczeń26 - wydatki'!$D9-'Styczeń26 - wydatki'!$F9 -> 0 | F9: =20+50+10 -> 80 | H9: 13 | I9: lekarz | J9: 300 | O9: NEW CAR | P9: =6660+1230+100+10+1000+1000+1000+1000+1500+1500 -> 15000 | Q9: po I
B10: 19 | C10: auto | D10: 500 | E10: ='Styczeń26 - wydatki'!$D10-'Styczeń26 - wydatki'!$F10 -> 0 | F10: 500 | H10: 17 | I10: chemia | J10: 50 | O10: GAZ | P10: =127+100+152+173+163+150+65-178-300 -> 452 | Q10: po I
B11: 21 | C11: fryzjer | D11: 50 | E11: ='Styczeń26 - wydatki'!$D11-'Styczeń26 - wydatki'!$F11 -> 0 | F11: 50 | H11: 18 | I11: mieszkanie | J11: 100 | P11: =P8+P9+P10 -> 20475
B12: 26 | C12: auto new | D12: 1500 | E12: ='Styczeń26 - wydatki'!$D12-'Styczeń26 - wydatki'!$F12 -> 0 | F12: 1500 | H12: 20 | I12: swieta | J12: 100 | O12: auto | P12: 500 | Q12: po XII
B13: 27 | C13: Kieszkonkowe D | D13: 500 | E13: =D13-F13 -> 0 | F13: 500 | H13: 22 | I13: fryzjer | J13: 50
C14: RAZEM | D14: =SUM(D4:D13) -> 4655 | E14: =SUM(E4:E13) -> 0 | H14: 23 | I14: koszty roczne | J14: 350
H15: 25 | I15: konkursy | J15: 50
B16: Koszty dynamiczne Damian | H16: 28 | I16: Kieszkonkowe M | J16: 500
C17: Rodzaj | D17: Budżet | E17: Pozostało | F17: Wydano | I17: RAZEM | J17: =SUM(J4:J16) -> 6045 | K17: =SUM(K4:K16) -> 0 | L17: =SUM(L4:L16) -> 0 | O17: =5310-206+19+83+36 -> 5242 | Q17: =68-52 -> 16
C18: Poduszka finansowa | D18: 500 | E18: ='Styczeń26 - wydatki'!$D18-F18 -> 0 | F18: 500
C19: Dom | D19: 400 | E19: ='Styczeń26 - wydatki'!$D19-F19 -> 0 | F19: 400 | H19: Koszty dynamiczne Malwina
C20: Tv | E20: ='Styczeń26 - wydatki'!$D20-F20 -> 0 | I20: Rodzaj | J20: Budżet | K20: Pozostało | L20: Wydano
C21: RAZEM | D21: =SUM(D18:D20) -> 900 | E21: =SUM(E18:E20) -> 0 | F21: =SUM(F18:F20) -> 900 | H21: 6 | I21: Przedszkole | J21: 1077
H22: 15 | I22: Dzieci | J22: 200
B23: Pozostałe Damian | H23: 16 | I23: Apteka | J23: 100
C24: Rodzaj | D24: Budżet | E24: Pozostało | F24: Wydano | I24: Urodziny dzieci | J24: 100
B25: 10 | C25: Woda | D25: 50 | E25: 0 | F25: 50 | I25: Maja lutcza | J25: 50
C26: Mama Bukiet | E26: =D26-F26 -> 0 | H26: 21 | I26: Wakacje | J26: 400
C27: Ostrza | E27: =D27-F27 -> 0 | H27: 25 | I27: Zabawowe | J27: 400
B28: 23 | C28: Prąd | E28: =D28-F28 -> 0 | H28: 31 | I28: Emerytura Rodziców | J28: 100
C29: Siłka | D29: 300 | E29: =D29-F29 -> 0 | F29: 300 | I29: RAZEM | J29: =SUM(J21:J28) -> 2427 | K29: =SUM(K21:K27) -> 0 | L29: =SUM(L21:L27) -> 0
C30: ladowarka | E30: =D30-F30 -> 0
C31: sylwek | E31: =D31-F31 -> 0 | H31: Pozostałe Malwina
C32: cookido | D32: 199 | E32: =D32-F32 -> 0 | F32: 199 | I32: Rodzaj | J32: Budżet | K32: Pozostało | L32: Wydano
B33: 30 | C33: URO BARTI | E33: =D33-F33 -> 0 | H33: 22 | I33: Podatek
C34: youtube | D34: 100 | E34: =D34-F34 -> 0 | F34: 100 | I34: Czynsz Mieszkanie | J34: 350
C35: RAZEM | D35: =SUM(D25:D34) -> 649 | E35: =SUM(E25:E34) -> 0 | F35: =SUM(F25:F34) -> 649 | H35: 24 | I35: Orawski
H36: 29 | I36: Telefon
C37: pozostało I | D37: =E35+E21+E14 -> 0 | E37: 150 | I37: premia
C38: pozostało XI | H38: 26 | I38: Uro Nela
C39: Total | E39: =E37+E38+D37 -> 150 | I39: dzin dziadkow | J39: 200
I41: RAZEM | J41: =SUM(J33:J40) -> 550 | K41: =SUM(K33:K39) -> 0 | L41: =SUM(L33:L39) -> 0
...

Sheet Grudzień25- wydatki
A1: \
B2: Koszty stałe Damian | H2: Koszty stałe Malwina | N2: Kolumna nr 1 | O2: Wypłaty | P2: Suma | Q2: Koszty stałe | R2: Koszty dyn. | S2: Pozostałe | T2: Podsumowanie
C3: Rodzaj | D3: Budżet | E3: Pozostało | F3: Wydano | I3: Rodzaj | J3: Budżet | K3: Pozostało | L3: Wydano | N3: Damian | O3: =7260+111 -> 7371 | P3: =Q3+R3+S3 -> 6375 | Q3: =D14 -> 4716 | R3: =D21 -> 1050 | S3: =D35 -> 609 | T3: =O3-P3 -> 996
B4: 2 | C4: internet | D4: 85 | E4: ='Grudzień25- wydatki'!$D4-'Grudzień25- wydatki'!$F4 -> 0 | F4: 85 | H4: 1 | I4: rata | J4: 3400 | N4: Malwina | O4: 9941 | P4: =Q4+R4+S4 -> 10937 | Q4: =J17 -> 6045 | R4: =J29 -> 2741 | S4: =J41 -> 2151 | T4: =O4-P4 -> -996
B5: 4 | C5: telefon | D5: 40 | E5: ='Grudzień25- wydatki'!$D5-'Grudzień25- wydatki'!$F5 -> 0 | F5: =40 -> 40 | H5: 3 | I5: woda | J5: 140 | N5: Suma | O5: =K43=O3+O4 -> TRUE | P5: =Q5+R5+S5 -> 17312 | Q5: =Q3+Q4 -> 10761 | R5: =R3+R4 -> 3791 | S5: =S3+S4 -> 2760
B6: 7 | C6: paliwo | D6: 800 | E6: ='Grudzień25- wydatki'!$D6-'Grudzień25- wydatki'!$F6 -> 0 | F6: =140+200+100+88.61+260+9+2.39 -> 800 | H6: 9 | I6: jedzenie | J6: 800
B7: 8 | C7: jedzenie | D7: 800 | E7: ='Grudzień25- wydatki'!$D7-'Grudzień25- wydatki'!$F7 -> 0.42 | F7: =13.9+13.28+42.5+22.91+177+70.99+18.21+43.2+86.18+48.47+122.44+11.98+76.17+16.35+36 -> 799.58 | G7: do 07,01 | H7: 11 | I7: smieci | J7: 140 | N7: Oszczędnościowe
B8: 5 | C8: Gaz | D8: 300 | E8: ='Grudzień25- wydatki'!$D8-F8 -> 0 | F8: 300 | H8: 12 | I8: izba | J8: 65 | N8: PEKAO | O8: DOM | P8: =4230+261+318-1650+300-223+300-250+250+228+453+350-332-350+358-120+500+400 -> 5023 | Q8: po I
B9: 14 | C9: rozne | D9: 111 | E9: ='Grudzień25- wydatki'!$D9-'Grudzień25- wydatki'!$F9 -> 0 | F9: =10+30+10+10+6+16+29 -> 111 | G9: skarpetki jak zostanie dopisane | H9: 13 | I9: lekarz | J9: 300 | O9: NEW CAR | P9: =6660+1230+100+10+1000+1000+1000+1000+1500+1500 -> 15000 | Q9: po I
B10: 19 | C10: auto | D10: 500 | E10: ='Grudzień25- wydatki'!$D10-'Grudzień25- wydatki'!$F10 -> 0 | F10: 500 | H10: 17 | I10: chemia | J10: 50 | O10: GAZ | P10: =127+100+152+173+163+150+65-178 -> 752 | Q10: po XII
B11: 21 | C11: fryzjer | D11: 50 | E11: ='Grudzień25- wydatki'!$D11-'Grudzień25- wydatki'!$F11 -> 0 | F11: 50 | H11: 18 | I11: mieszkanie | J11: 100 | P11: =P8+P9+P10 -> 20775
B12: 26 | C12: auto new | D12: 1500 | E12: ='Grudzień25- wydatki'!$D12-'Grudzień25- wydatki'!$F12 -> 0 | F12: 1500 | H12: 20 | I12: swieta | J12: 100 | O12: auto | P12: 1713 | Q12: po XII
B13: 27 | C13: Kieszkonkowe D | D13: 530 | E13: =D13-F13 -> 0 | F13: =23+400+13+94 -> 530 | H13: 22 | I13: fryzjer | J13: 50
C14: RAZEM | D14: =SUM(D4:D13) -> 4716 | E14: =SUM(E4:E13) -> 0.42 | H14: 23 | I14: koszty roczne | J14: 350
H15: 25 | I15: konkursy | J15: 50
B16: Koszty dynamiczne Damian | H16: 28 | I16: Kieszkonkowe M | J16: 500
C17: Rodzaj | D17: Budżet | E17: Pozostało | F17: Wydano | I17: RAZEM | J17: =SUM(J4:J16) -> 6045 | K17: =SUM(K4:K16) -> 0 | L17: =SUM(L4:L16) -> 0 | O17: =5310-206+19+83+36 -> 5242 | Q17: =68-52 -> 16
C18: Poduszka finansowa | D18: 500 | E18: ='Grudzień25- wydatki'!$D18-F18 -> 0 | F18: 500
C19: Dom | D19: 500 | E19: ='Grudzień25- wydatki'!$D19-F19 -> 0 | F19: 500 | H19: Koszty dynamiczne Malwina | N19: jedzenie | O19: =5+216.66+47.96 -> 269.62
C20: Tv | D20: 50 | E20: ='Grudzień25- wydatki'!$D20-F20 -> 50 | I20: Rodzaj | J20: Budżet | K20: Pozostało | L20: Wydano | N20: wyjazd | O20: =62.44+47 -> 109.44
C21: RAZEM | D21: =SUM(D18:D20) -> 1050 | E21: =SUM(E18:E20) -> 50 | F21: =SUM(F18:F20) -> 1000 | H21: 6 | I21: Przedszkole | J21: 1138
H22: 15 | I22: Dzieci | J22: 200
B23: Pozostałe Damian | H23: 16 | I23: Apteka | J23: 100
C24: Rodzaj | D24: Budżet | E24: Pozostało | F24: Wydano | I24: Urodziny dzieci | J24: 100
B25: 10 | C25: Woda | D25: 50 | E25: =D25-F25 -> 0 | F25: 50 | I25: Maja lutcza | J25: 50
C26: Mama Bukiet | D26: 109 | E26: =D26-F26 -> 0 | F26: 109 | H26: 21 | I26: Wakacje | J26: 553
C27: Ostrza | D27: 50 | E27: =D27-F27 -> 0 | F27: 50 | H27: 25 | I27: Zabawowe | J27: 500
B28: 23 | C28: Prąd | E28: =D28-F28 -> 0 | H28: 31 | I28: Emerytura Rodziców | J28: 100
C29: Siłka | D29: 300 | E29: =D29-F29 -> 0 | F29: 300 | I29: RAZEM | J29: =SUM(J21:J28) -> 2741 | K29: =SUM(K21:K27) -> 0 | L29: =SUM(L21:L27) -> 0
C30: ladowarka | E30: =D30-F30 -> 0
C31: sylwek | D31: 100 | E31: =D31-F31 -> 100 | H31: Pozostałe Malwina
E32: =D32-F32 -> 0 | I32: Rodzaj | J32: Budżet | K32: Pozostało | L32: Wydano
B33: 30 | C33: URO BARTI | E33: =D33-F33 -> 0 | H33: 22 | I33: Podatek
C34: Znicze | E34: =D34-F34 -> 0 | I34: Czynsz Mieszkanie | J34: 350
C35: RAZEM | D35: =SUM(D25:D34) -> 609 | E35: =SUM(E25:E34) -> 100 | F35: =SUM(F25:F34) -> 509 | H35: 24 | I35: Orawski | J35: 600
H36: 29 | I36: Telefon | J36: 799
C37: pozostało XII | D37: =E35+E21+E14 -> 150.42 | E37: 0 | I37: premia | J37: 300
C38: pozostało XI | H38: 26 | I38: Uro Nela | J38: 102
C39: Total | E39: =E37+E38+D37 -> 150.42
I41: RAZEM | J41: =SUM(J33:J40) -> 2151 | K41: =SUM(K33:K39) -> 0 | L41: =SUM(L33:L39) -> 0
...

Sheet Listopad25- wydatki
A1: \
B2: Koszty stałe Damian | H2: Koszty stałe Malwina | N2: Kolumna nr 1 | O2: Wypłaty | P2: Suma | Q2: Koszty stałe | R2: Koszty dyn. | S2: Pozostałe | T2: Podsumowanie
C3: Rodzaj | D3: Budżet | E3: Pozostało | F3: Wydano | I3: Rodzaj | J3: Budżet | K3: Pozostało | L3: Wydano | N3: Damian | O3: =7263+300 -> 7563 | P3: =Q3+R3+S3 -> 6707 | Q3: =D14 -> 6299 | R3: =D21 -> 358 | S3: =D35 -> 50 | T3: =O3-P3 -> 856
B4: 2 | C4: internet | D4: 85 | E4: ='Listopad25- wydatki'!$D4-'Listopad25- wydatki'!$F4 -> 0 | F4: =25+60 -> 85 | H4: 1 | I4: rata | J4: 3400 | N4: Malwina | O4: =7108+2300 -> 9408 | P4: =Q4+R4+S4 -> 10264 | Q4: =J17 -> 6536 | R4: =J29 -> 2345 | S4: =J41 -> 1383 | T4: =O4-P4 -> -856
B5: 4 | C5: telefon | D5: 40 | E5: ='Listopad25- wydatki'!$D5-'Listopad25- wydatki'!$F5 -> 0 | F5: =29+4+7 -> 40 | H5: 3 | I5: woda | J5: 140 | N5: Suma | O5: =K43=O3+O4 -> TRUE | P5: =Q5+R5+S5 -> 16971 | Q5: =Q3+Q4 -> 12835 | R5: =R3+R4 -> 2703 | S5: =S3+S4 -> 1433
B6: 7 | C6: paliwo | D6: 800 | E6: ='Listopad25- wydatki'!$D6-'Listopad25- wydatki'!$F6 -> 0 | F6: =180+235+99+95+191 -> 800 | H6: 9 | I6: jedzenie | J6: 800
B7: 8 | C7: jedzenie | D7: 800 | E7: ='Listopad25- wydatki'!$D7-'Listopad25- wydatki'!$F7 -> -0.4 | F7: =20+33.71+11.18+16.66+104.63+3.99+29.55+170.65+17.88+59+110+12.74+57.7+85+36.87+5.97+41.87+35-52 -> 800.4 | G7: 6.12 | H7: 11 | I7: smieci | J7: 140 | N7: Oszczędnościowe
B8: 5 | C8: Gaz | D8: 300 | E8: ='Listopad25- wydatki'!$D8-F8 -> 0 | F8: =235+65 -> 300 | H8: 12 | I8: izba | J8: 65 | N8: PEKAO | O8: DOM | P8: =4230+261+318-1650+300-223+300-250+250+228+453+350-332-350+358-120 -> 4123 | Q8: po XI
B9: 14 | C9: rozne | D9: 100 | E9: ='Listopad25- wydatki'!$D9-'Listopad25- wydatki'!$F9 -> 0 | F9: =30+20+22+3+14+11 -> 100 | H9: 13 | I9: lekarz | J9: 300 | O9: NEW CAR | P9: =6660+1230+100+10+1000+1000+1000+1000 -> 12000 | Q9: po XI
B10: 19 | C10: auto | D10: 500 | E10: ='Listopad25- wydatki'!$D10-'Listopad25- wydatki'!$F10 -> 0 | F10: 500 | H10: 17 | I10: chemia | J10: 100 | O10: GAZ | P10: =127+100+152+173+163+150+65 -> 930 | Q10: po XI
B11: 21 | C11: fryzjer | D11: 50 | E11: ='Listopad25- wydatki'!$D11-'Listopad25- wydatki'!$F11 -> 0 | F11: 50 | H11: 18 | I11: mieszkanie | J11: 100 | P11: =P8+P9+P10 -> 17053
B12: 26 | C12: auto new | D12: 1000 | E12: ='Listopad25- wydatki'!$D12-'Listopad25- wydatki'!$F12 -> 0 | F12: 1000 | H12: 20 | I12: swieta | J12: 100 | O12: auto | P12: =1510+500+500+500-900-370+330-20 -> 2050 | Q12: po X
B13: 27 | C13: Kieszkonkowe D | D13: 2624 | E13: =D13-F13 -> 0 | F13: =7+960+226+23+108+30+1250+20 -> 2624 | H13: 22 | I13: fryzjer | J13: 50
C14: RAZEM | D14: =SUM(D4:D13) -> 6299 | E14: =SUM(E4:E13) -> -0.4 | H14: 23 | I14: koszty roczne | J14: 350
H15: 25 | I15: konkursy | J15: 50
B16: Koszty dynamiczne Damian | H16: 28 | I16: Kieszkonkowe M | J16: 941
C17: Rodzaj | D17: Budżet | E17: Pozostało | F17: Wydano | I17: RAZEM | J17: =SUM(J4:J16) -> 6536 | K17: =SUM(K4:K16) -> 0 | L17: =SUM(L4:L16) -> 0 | O17: =5310-206+19+83+36 -> 5242 | Q17: =68-52 -> 16
C18: sanok | E18: ='Listopad25- wydatki'!$D18-F18 -> 0
C19: Dom | D19: 358 | E19: ='Listopad25- wydatki'!$D19-F19 -> 0 | F19: =358 -> 358 | H19: Koszty dynamiczne Malwina
C20: Tv | E20: ='Listopad25- wydatki'!$D20-F20 -> 0 | I20: Rodzaj | J20: Budżet | K20: Pozostało | L20: Wydano
C21: RAZEM | D21: =SUM(D18:D20) -> 358 | E21: =SUM(E18:E20) -> 0 | F21: =SUM(F18:F20) -> 358 | H21: 6 | I21: Przedszkole | J21: 1095
H22: 15 | I22: Dzieci | J22: 200 | S22: 50fryzjer
B23: Pozostałe Damian | H23: 16 | I23: Apteka | J23: 100 | T23: 32
C24: Rodzaj | D24: Budżet | E24: Pozostało | F24: Wydano | I24: Urodziny dzieci | J24: 100 | S24: M | T24: 42elfi,punkt049-32
B25: 10 | C25: Woda | D25: 50 | E25: =D25-F25 -> 0 | F25: =35+15 -> 50 | I25: Maja lutcza | J25: 50 | T25: 25tort,zakupy52
C26: Szmatki | E26: =D26-F26 -> 0 | H26: 21 | I26: Wakacje | J26: 400 | T26: kwiaty babcia 109
C27: Youtube | E27: =D27-F27 -> 0 | H27: 25 | I27: Zabawowe | J27: 400 | T27: 260 + 50 = 310
B28: 23 | C28: Prąd | E28: =D28-F28 -> 0 | H28: 31 | I28: pierogi
E29: =D29-F29 -> 0 | I29: RAZEM | J29: =SUM(J21:J28) -> 2345 | K29: =SUM(K21:K27) -> 0 | L29: =SUM(L21:L27) -> 0
C30: ladowarka | E30: =D30-F30 -> 0
C31: sylwek | E31: =D31-F31 -> 0 | H31: Pozostałe Malwina
E32: =D32-F32 -> 0 | I32: Rodzaj | J32: Budżet | K32: Pozostało | L32: Wydano
B33: 30 | C33: URO BARTI | E33: =D33-F33 -> 0 | H33: 22 | I33: Podatek | J33: 89
C34: Znicze | E34: =D34-F34 -> 0 | I34: bilety | J34: 638
C35: RAZEM | D35: =SUM(D25:D34) -> 50 | E35: =SUM(E25:E34) -> 0 | F35: =SUM(F25:F34) -> 50 | H35: 24 | I35: uro barti | J35: 367
H36: 29 | I36: hebda | J36: 69
C37: pozostało I | D37: =E35+E21+E14 -> -0.4 | E37: 0 | I37: olinii | J37: 220
C38: pozostało XII | H38: 26 | I38: puro Hania
C39: Total | E39: =E37+E38+D37 -> -0.4
D40: kwiaty babcia | E40: 0
...

Sheet Październik25- wydatki
A1: \
B2: Koszty stałe Damian | H2: Koszty stałe Malwina | N2: Kolumna nr 1 | O2: Wypłaty | P2: Suma | Q2: Koszty stałe | R2: Koszty dyn. | S2: Pozostałe | T2: Podsumowanie
C3: Rodzaj | D3: Budżet | E3: Pozostało | F3: Wydano | I3: Rodzaj | J3: Budżet | K3: Pozostało | L3: Wydano | N3: Damian | O3: 5469 | P3: =Q3+R3+S3 -> 5083 | Q3: =D14 -> 4175 | R3: =D21 -> 480 | S3: =D35 -> 428 | T3: =O3-P3 -> 386
B4: 2 | C4: internet | D4: 85 | E4: ='Październik25- wydatki'!$D4-'Październik25- wydatki'!$F4 -> 0 | F4: 85 | H4: 1 | I4: rata | J4: 3400 | N4: Malwina | O4: =5662+2250+1375 -> 9287 | P4: =Q4+R4+S4 -> 9673 | Q4: =J17 -> 6045 | R4: =J29 -> 3383 | S4: =J41 -> 245 | T4: =O4-P4 -> -386
B5: 4 | C5: telefon | D5: 40 | E5: ='Październik25- wydatki'!$D5-'Październik25- wydatki'!$F5 -> 0 | F5: 40 | H5: 3 | I5: woda | J5: 140 | N5: Suma | O5: =K43=O3+O4 -> TRUE | P5: =Q5+R5+S5 -> 14756 | Q5: =Q3+Q4 -> 10220 | R5: =R3+R4 -> 3863 | S5: =S3+S4 -> 673
B6: 7 | C6: paliwo | D6: 800 | E6: ='Październik25- wydatki'!$D6-'Październik25- wydatki'!$F6 -> 0 | F6: =99+330+98+100+23+150 -> 800 | H6: 9 | I6: jedzenie | J6: 800
B7: 8 | C7: jedzenie | D7: 800 | E7: ='Październik25- wydatki'!$D7-'Październik25- wydatki'!$F7 -> 0.12 | F7: =32.83+22.39+5.58+42.08+101.64+36.83+4.59+36.23+21.42+58.33+96.28+113+6.5+57.08+50.82+20.67+16.67+50.3+11.64+15 -> 799.88 | H7: 11 | I7: smieci | J7: 140 | N7: Oszczędnościowe
B8: 5 | C8: Gaz | D8: 300 | E8: ='Październik25- wydatki'!$D8-F8 -> 0 | F8: =150+150 -> 300 | H8: 12 | I8: izba | J8: 65 | N8: PEKAO | O8: DOM | P8: =4230+261+318-1650+300-223+300-250+250+228+453+350-332-350 -> 3885 | Q8: po X
B9: 14 | C9: rozne | D9: 100 | E9: ='Październik25- wydatki'!$D9-'Październik25- wydatki'!$F9 -> 0 | F9: =28+3+17+48+3+1 -> 100 | H9: 13 | I9: lekarz | J9: 300 | O9: NEW CAR | P9: =6660+1230+100+10+1000+1000+1000 -> 11000 | Q9: po X
B10: 19 | C10: auto | D10: 500 | E10: ='Październik25- wydatki'!$D10-'Październik25- wydatki'!$F10 -> 0 | F10: 500 | H10: 17 | I10: chemia | J10: 50 | O10: GAZ | P10: =127+100+152+173+163+150 -> 865 | Q10: po X
B11: 21 | C11: fryzjer | D11: 50 | E11: ='Październik25- wydatki'!$D11-'Październik25- wydatki'!$F11 -> 0 | F11: 50 | H11: 18 | I11: mieszkanie | J11: 100 | P11: =P8+P9+P10 -> 15750
B12: 26 | C12: auto new | D12: 1000 | E12: ='Październik25- wydatki'!$D12-'Październik25- wydatki'!$F12 -> 0 | F12: 1000 | H12: 20 | I12: swieta | J12: 100 | O12: auto | P12: =1510+500+500+500-900-370+330-20 -> 2050 | Q12: po X
B13: 27 | C13: Kieszkonkowe D | D13: 500 | E13: ='Październik25- wydatki'!$D13-'Październik25- wydatki'!$F13 -> 0 | F13: =300+26+25+46+3+27+45+10+18 -> 500 | H13: 22 | I13: fryzjer | J13: 50
C14: RAZEM | D14: =SUM(D4:D13) -> 4175 | E14: =SUM(E4:E13) -> 0.12 | F14: =SUM(F4:F13) -> 4174.88 | H14: 23 | I14: koszty roczne | J14: 350
H15: 25 | I15: konkursy | J15: 50 | L15: 20
B16: Koszty dynamiczne Damian | H16: 28 | I16: Kieszkonkowe M | J16: 500
C17: Rodzaj | D17: Budżet | E17: Pozostało | F17: Wydano | I17: RAZEM | J17: =SUM(J4:J16) -> 6045 | K17: =SUM(K4:K16) -> 0 | L17: =SUM(L4:L16) -> 20 | O17: =5310-206+19+83+36 -> 5242 | Q17: =68-52 -> 16
C18: sanok | D18: 130 | E18: ='Październik25- wydatki'!$D18-F18 -> 0 | F18: 130
C19: Dom | D19: 350 | E19: ='Październik25- wydatki'!$D19-F19 -> 0 | F19: 350 | H19: Koszty dynamiczne Malwina
C20: Tv | E20: ='Październik25- wydatki'!$D20-F20 -> 0 | I20: Rodzaj | J20: Budżet | K20: Pozostało | L20: Wydano
C21: RAZEM | D21: =SUM(D18:D20) -> 480 | E21: =SUM(E18:E20) -> 0 | F21: =SUM(F18:F20) -> 480 | H21: 6 | I21: Przedszkole | J21: 1167
H22: 15 | I22: Dzieci | J22: 200
B23: Pozostałe Damian | H23: 16 | I23: Apteka | J23: 100
C24: Rodzaj | D24: Budżet | E24: Pozostało | F24: Wydano | I24: kaucja | J24: 1100
B25: 10 | C25: Woda | D25: 50 | E25: =D25-F25 -> 0 | F25: 50 | I25: ksiazki | J25: 50
C26: Szmatki | D26: 69 | E26: =D26-F26 -> 0 | F26: 69 | H26: 21 | I26: Wakacje | J26: 400
C27: Youtube | E27: =D27-F27 -> 0 | H27: 25 | I27: Zabawowe | J27: 350
B28: 23 | C28: Prąd | D28: 54 | E28: =D28-F28 -> 0 | F28: 54 | H28: 31 | I28: pierogi | J28: 16
E29: =D29-F29 -> 0 | I29: RAZEM | J29: =SUM(J21:J28) -> 3383 | K29: =SUM(K21:K27) -> 0 | L29: =SUM(L21:L27) -> 0
C30: ladowarka | E30: =D30-F30 -> 0
C31: sylwek | D31: 100 | E31: =D31-F31 -> 100 | H31: Pozostałe Malwina
E32: =D32-F32 -> 0 | I32: Rodzaj | J32: Budżet | K32: Pozostało | L32: Wydano
B33: 30 | C33: URO BARTI | D33: 105 | E33: =D33-F33 -> 0 | F33: 105 | H33: 22 | I33: Podatek
C34: Znicze | D34: 50 | E34: =D34-F34 -> 0 | F34: =30+20 -> 50 | I34: uro tata
C35: RAZEM | D35: =SUM(D25:D34) -> 428 | E35: =SUM(E25:E34) -> 100 | F35: =SUM(F25:F34) -> 328 | H35: 24 | I35: Maja lutcza | J35: 50
H36: 29 | I36: uro Amelka | J36: 100
C37: pozostało I | D37: =E35+E21+E14 -> 100.12 | E37: 0 | I37: dlugi | J37: 95
C38: pozostało XII | H38: 26 | I38: puro Hania
C39: Total | E39: =E37+E38+D37 -> 100.12
I41: RAZEM | J41: =SUM(J33:J40) -> 245 | K41: =SUM(K33:K39) -> 0 | L41: =SUM(L33:L39) -> 0
...

Sheet Wrzesień25- wydatki
A1: \
B2: Koszty stałe Damian | H2: Koszty stałe Malwina | N2: Kolumna nr 1 | O2: Wypłaty | P2: Suma | Q2: Koszty stałe | R2: Koszty dyn. | S2: Pozostałe | T2: Podsumowanie
C3: Rodzaj | D3: Budżet | E3: Pozostało | F3: Wydano | I3: Rodzaj | J3: Budżet | K3: Pozostało | L3: Wydano | N3: Damian | O3: 5300 | P3: =Q3+R3+S3 -> 4495 | Q3: =D14 -> 4175 | R3: =D21 -> 100 | S3: =D35 -> 220 | T3: =O3-P3 -> 805
B4: 2 | C4: internet | D4: 85 | E4: ='Wrzesień25- wydatki'!$D4-'Wrzesień25- wydatki'!$F4 -> 0 | F4: 85 | H4: 1 | I4: rata | J4: 3400 | N4: Malwina | O4: 7912 | P4: =Q4+R4+S4 -> 8717 | Q4: =J17 -> 6050 | R4: =J29 -> 1917 | S4: =J41 -> 750 | T4: =O4-P4 -> -805
B5: 4 | C5: telefon | D5: 40 | E5: ='Wrzesień25- wydatki'!$D5-'Wrzesień25- wydatki'!$F5 -> 0 | F5: 40 | H5: 3 | I5: woda | J5: 140 | N5: Suma | O5: =K43=O3+O4 -> TRUE | P5: =Q5+R5+S5 -> 13212 | Q5: =Q3+Q4 -> 10225 | R5: =R3+R4 -> 2017 | S5: =S3+S4 -> 970
B6: 5 | C6: paliwo | D6: 800 | E6: ='Wrzesień25- wydatki'!$D6-'Wrzesień25- wydatki'!$F6 -> 0 | F6: =95+98+215+248+99+45 -> 800 | H6: 7 | I6: jedzenie | J6: 800
B7: 6 | C7: jedzenie | D7: 800 | E7: ='Wrzesień25- wydatki'!$D7-'Wrzesień25- wydatki'!$F7 -> -0.26 | F7: =214+5.5+18.78+72.15+20.87+55+52+8.99+15.87+15.12+14.02+13.66+198.25+21.81+49.24+25 -> 800.26 | H7: 9 | I7: smieci | J7: 140 | N7: Oszczędnościowe
B8: 5 | C8: Gaz | D8: 300 | E8: ='Wrzesień25- wydatki'!$D8-F8 -> 0 | F8: 300 | H8: 10 | I8: izba | J8: 65 | N8: PEKAO | O8: DOM | P8: =4230+261+318-1650+300-223+300-250+250+228+453 -> 4217 | Q8: po VIII
B9: 12 | C9: rozne | D9: 100 | E9: ='Wrzesień25- wydatki'!$D9-'Wrzesień25- wydatki'!$F9 -> 0 | F9: =9+8+4+4+59+16 -> 100 | H9: 11 | I9: lekarz | J9: 300 | O9: NEW CAR | P9: =6660+1230+100+10+1000+1000 -> 10000 | Q9: po IX
B10: 15 | C10: auto | D10: 500 | E10: ='Wrzesień25- wydatki'!$D10-'Wrzesień25- wydatki'!$F10 -> 0 | F10: 500 | H10: 13 | I10: chemia | J10: 55 | O10: GAZ | P10: =127+100+152+173+163 -> 715 | Q10: po IX
B11: 17 | C11: fryzjer | D11: 50 | E11: ='Wrzesień25- wydatki'!$D11-'Wrzesień25- wydatki'!$F11 -> 0 | F11: 50 | H11: 14 | I11: mieszkanie | J11: 100 | P11: =P8+P9+P10 -> 14932
B12: 21 | C12: auto new | D12: 1000 | E12: ='Wrzesień25- wydatki'!$D12-'Wrzesień25- wydatki'!$F12 -> 0 | F12: 1000 | H12: 16 | I12: swieta | J12: 100 | O12: auto | P12: =1510+500+500+500-900-370+330-20 -> 2050 | Q12: po VII
B13: 22 | C13: Kieszkonkowe D | D13: 500 | E13: ='Wrzesień25- wydatki'!$D13-'Wrzesień25- wydatki'!$F13 -> 0 | F13: =310+25+61+23+81 -> 500 | H13: 18 | I13: fryzjer | J13: 50
C14: RAZEM | D14: =SUM(D4:D13) -> 4175 | E14: =SUM(E4:E13) -> -0.26 | F14: =SUM(F4:F13) -> 4175.26 | H14: 19 | I14: koszty roczne | J14: 350
H15: 20 | I15: konkursy | J15: 50
B16: Koszty dynamiczne Damian | H16: 23 | I16: Kieszkonkowe M | J16: 500
C17: Rodzaj | D17: Budżet | E17: Pozostało | F17: Wydano | I17: RAZEM | J17: =SUM(J4:J16) -> 6050 | K17: =SUM(K4:K16) -> 0 | L17: =SUM(L4:L16) -> 0 | O17: =5310-206+19+83+36 -> 5242 | Q17: =68-52 -> 16
C18: Sanok | D18: 100 | E18: ='Wrzesień25- wydatki'!$D18-F18 -> 0 | F18: 100
C19: Dom | E19: ='Wrzesień25- wydatki'!$D19-F19 -> 0 | H19: Koszty dynamiczne Malwina
C20: Tv | E20: ='Wrzesień25- wydatki'!$D20-F20 -> 0 | I20: Rodzaj | J20: Budżet | K20: Pozostało | L20: Wydano
C21: RAZEM | D21: =SUM(D18:D20) -> 100 | E21: =SUM(E18:E20) -> 0 | F21: =SUM(F18:F20) -> 100 | H21: 6 | I21: Przedszkole | J21: 1167
H22: 13 | I22: Dzieci | J22: 200
B23: Pozostałe Damian | H23: 14 | I23: Apteka | J23: 100
C24: Rodzaj | D24: Budżet | E24: Pozostało | F24: Wydano | I24: książki | J24: 50
B25: 8 | C25: Woda | D25: 50 | E25: =D25-F25 -> 0 | F25: =30+20 -> 50 | I25: maliny | R25: rossman | S25: 44.48
C26: Szmatki | E26: =D26-F26 -> 0 | H26: 21 | I26: Wakacje | R26: rossman | S26: 61.7
C27: Youtube | E27: =D27-F27 -> 0 | H27: 25 | I27: Zabawowe | J27: 400
B28: 23 | C28: Prąd | D28: 70 | E28: =D28-F28 -> 0 | F28: =53+17 -> 70
C29: gumki | D29: 51 | E29: =D29-F29 -> 0 | F29: 51 | I29: RAZEM | J29: =SUM(J21:J28) -> 1917 | K29: =SUM(K21:K27) -> 0 | L29: =SUM(L21:L27) -> 0 | R29: jedzenie | S29: 44.48 | T29: 32.83 | U29: 22.39 | V29: 5.58 | W29: 42.08 | X29: 101.64 | Y29: 19.99 | Z29: 36.83
C30: ladowarka | D30: 49 | E30: =D30-F30 -> 0 | F30: 49
H31: Pozostałe Malwina
I32: Rodzaj | J32: Budżet | K32: Pozostało | L32: Wydano
H33: 22 | I33: Podatek | J33: 90
I34: uro tata | J34: 110
C35: RAZEM | D35: =SUM(D25:D34) -> 220 | E35: =SUM(E25:E34) -> 0 | F35: =SUM(F25:F30) -> 220 | H35: 20 | I35: Maja lutcza | J35: 50
H36: 24 | I36: ur o Barti | J36: 230
C37: pozostało I | D37: =E35+E21+E14 -> -0.26 | E37: 0 | I37: kaucja | J37: 100
C38: pozostało XII | E38: 169 | H38: 26 | I38: puro Hania | J38: 70
C39: Total | E39: =E37+E38+D37 -> 168.74 | I39: uro Ignaś | J39: 100
I41: RAZEM | J41: =SUM(J33:J40) -> 750 | K41: =SUM(K33:K39) -> 0 | L41: =SUM(L33:L39) -> 0
...

Sheet Sierpień25 - wydatki
A1: \
B2: Koszty stałe Damian | H2: Koszty stałe Malwina | N2: Kolumna nr 1 | O2: Wypłaty | P2: Suma | Q2: Koszty stałe | R2: Koszty dyn. | S2: Pozostałe | T2: Podsumowanie
C3: Rodzaj | D3: Budżet | E3: Pozostało | F3: Wydano | I3: Rodzaj | J3: Budżet | K3: Pozostało | L3: Wydano | N3: Damian | O3: =5379+295 -> 5674 | P3: =Q3+R3+S3 -> 4857 | Q3: =D14 -> 4075 | R3: =D21 -> 553 | S3: =D35 -> 229 | T3: =O3-P3 -> 817
B4: 2 | C4: internet | D4: 85 | E4: ='Sierpień25 - wydatki'!$D4-'Sierpień25 - wydatki'!$F4 -> 0 | F4: 85 | H4: 1 | I4: rata | J4: 3400 | N4: Malwina | O4: =7755+447 -> 8202 | P4: =Q4+R4+S4 -> 9019 | Q4: =J17 -> 6045 | R4: =J29 -> 2529 | S4: =J41 -> 445 | T4: =O4-P4 -> -817
B5: 4 | C5: telefon | D5: 40 | E5: ='Sierpień25 - wydatki'!$D5-'Sierpień25 - wydatki'!$F5 -> 0 | F5: 40 | H5: 3 | I5: woda | J5: 140 | N5: Suma | O5: =K43=O3+O4 -> TRUE | P5: =Q5+R5+S5 -> 13876 | Q5: =Q3+Q4 -> 10120 | R5: =R3+R4 -> 3082 | S5: =S3+S4 -> 674
B6: 5 | C6: paliwo | D6: 700 | E6: ='Sierpień25 - wydatki'!$D6-'Sierpień25 - wydatki'!$F6 -> -0.25 | F6: =75+102+280+2+70.25+171 -> 700.25 | H6: 7 | I6: jedzenie | J6: 800
B7: 6 | C7: jedzenie | D7: 800 | E7: ='Sierpień25 - wydatki'!$D7-'Sierpień25 - wydatki'!$F7 -> 0 | F7: =31.5+45.92+24.17+35.71+11.59+1.49+39.43+8.68+68.24+19.47+97.07+42.53+117.5+35.13+47.52+122.78+65.91+6.59+6.59-28+0.18 -> 800 | H7: 9 | I7: smieci | J7: 140 | N7: Oszczędnościowe
B8: 5 | C8: Gaz | D8: 300 | E8: ='Sierpień25 - wydatki'!$D8-F8 -> 0 | F8: =127+173 -> 300 | H8: 10 | I8: izba | J8: 65 | N8: PEKAO | O8: DOM | P8: =4230+261+318-1650+300-223+300-250+250+228+453 -> 4217 | Q8: po VIII
B9: 12 | C9: rozne | D9: 100 | E9: ='Sierpień25 - wydatki'!$D9-'Sierpień25 - wydatki'!$F9 -> 0.12 | F9: =53.88+4+40+2 -> 99.88 | H9: 11 | I9: lekarz | J9: 300 | O9: NEW CAR | P9: =6660+1230+100+10+1000 -> 9000 | Q9: po VIII
B10: 15 | C10: auto | D10: 500 | E10: ='Sierpień25 - wydatki'!$D10-'Sierpień25 - wydatki'!$F10 -> 0 | F10: 500 | H10: 13 | I10: chemia | J10: 50 | O10: GAZ | P10: =127+100+152+173 -> 552 | Q10: po VIII
B11: 17 | C11: fryzjer | D11: 50 | E11: ='Sierpień25 - wydatki'!$D11-'Sierpień25 - wydatki'!$F11 -> 0 | F11: 50 | H11: 14 | I11: mieszkanie | J11: 100 | P11: =P8+P9+P10 -> 13769
B12: 21 | C12: auto new | D12: 1000 | E12: ='Sierpień25 - wydatki'!$D12-'Sierpień25 - wydatki'!$F12 -> 0 | F12: 1000 | H12: 16 | I12: swieta | J12: 100 | O12: auto | P12: =1510+500+500+500-900-370+330-20 -> 2050 | Q12: po VII
B13: 22 | C13: Kieszkonkowe D | D13: 500 | E13: ='Sierpień25 - wydatki'!$D13-'Sierpień25 - wydatki'!$F13 -> 0 | F13: =330+20+26+35+25+64 -> 500 | H13: 18 | I13: fryzjer | J13: 50
C14: RAZEM | D14: =SUM(D4:D13) -> 4075 | E14: =SUM(E4:E13) -> -0.13 | F14: =SUM(F4:F13) -> 4075.13 | H14: 19 | I14: koszty roczne | J14: 350
H15: 20 | I15: konkursy | J15: 50
B16: Koszty dynamiczne Damian | H16: 23 | I16: Kieszkonkowe M | J16: 500
C17: Rodzaj | D17: Budżet | E17: Pozostało | F17: Wydano | I17: RAZEM | J17: =SUM(J4:J16) -> 6045 | K17: =SUM(K4:K16) -> 0 | L17: =SUM(L4:L16) -> 0 | O17: =5310-206+19+83+36 -> 5242 | Q17: =68-52 -> 16
C18: Sanok | D18: 100 | E18: ='Sierpień25 - wydatki'!$D18-F18 -> 0 | F18: 100
C19: Dom | D19: 453 | E19: ='Sierpień25 - wydatki'!$D19-F19 -> 0 | F19: 453 | H19: Koszty dynamiczne Malwina
C20: Tv | E20: ='Sierpień25 - wydatki'!$D20-F20 -> 0 | I20: Rodzaj | J20: Budżet | K20: Pozostało | L20: Wydano
C21: RAZEM | D21: =SUM(D18:D20) -> 553 | E21: =SUM(E18:E20) -> 0 | F21: =SUM(F18:F20) -> 553 | H21: 6 | I21: Przedszkole | J21: 984
H22: 13 | I22: Dzieci | J22: 200
B23: Pozostałe Damian | H23: 14 | I23: Apteka | J23: 100
C24: Rodzaj | D24: Budżet | E24: Pozostało | F24: Wydano | I24: wesele | J24: 200
B25: 8 | C25: Woda | D25: 60 | E25: =D25-F25 -> 0 | F25: =20+20+10+10 -> 60 | I25: maliny | J25: 100
C26: Szmatki | D26: 69 | E26: =D26-F26 -> 69 | H26: 21 | I26: Wakacje | J26: 400
C27: Youtube | E27: =D27-F27 -> 0 | H27: 25 | I27: Zabawowe | J27: 400
B28: 23 | C28: Prąd | E28: =D28-F28 -> 0 | I28: ur taty | J28: 145
C29: Wojtek | E29: =D29-F29 -> 0 | I29: RAZEM | J29: =SUM(J21:J28) -> 2529 | K29: =SUM(K21:K27) -> 0 | L29: =SUM(L21:L27) -> 0
C30: Truskawki
C31: sylwek | D31: 100 | E31: 100 | H31: Pozostałe Malwina
I32: Rodzaj | J32: Budżet | K32: Pozostało | L32: Wydano
H33: 22 | I33: Podatek
I34: mikolaj prezent | J34: 100
C35: RAZEM | D35: =SUM(D25:D34) -> 229 | E35: =SUM(E25:E34) -> 169 | F35: =SUM(F25:F30) -> 60 | H35: 20 | I35: Maja lutcza | J35: 50
H36: 24 | I36: manka | J36: 145
C37: pozostało I | D37: =E35+E21+E14 -> 168.87 | E37: 0 | I37: kaucja | J37: 100
C38: pozostało XII | H38: 26 | I38: Szczoteczki
C39: Total | E39: =E37+E38+D37 -> 168.87 | I39: ksiazki | J39: 50
I40: Gaja
...

Sheet Lipiec25 - wydatki
A1: \
B2: Koszty stałe Damian | H2: Koszty stałe Malwina | N2: Kolumna nr 1 | O2: Wypłaty | P2: Suma | Q2: Koszty stałe | R2: Koszty dyn. | S2: Pozostałe | T2: Podsumowanie
C3: Rodzaj | D3: Budżet | E3: Pozostało | F3: Wydano | I3: Rodzaj | J3: Budżet | K3: Pozostało | L3: Wydano | N3: Damian | O3: 5095 | P3: =Q3+R3+S3 -> 5043 | Q3: =D14 -> 4455 | R3: =D21 -> 469 | S3: =D35 -> 119 | T3: =O3-P3 -> 52
B4: 2 | C4: internet | D4: 85 | E4: ='Lipiec25 - wydatki'!$D4-'Lipiec25 - wydatki'!$F4 -> 0 | F4: 85 | H4: 1 | I4: rata | J4: 3400 | N4: Malwina | O4: =6554+2200 -> 8754 | P4: =Q4+R4+S4 -> 8806 | Q4: =J17 -> 6257 | R4: =J29 -> 2028 | S4: =J41 -> 521 | T4: =O4-P4 -> -52
B5: 4 | C5: telefon | D5: 40 | E5: ='Lipiec25 - wydatki'!$D5-'Lipiec25 - wydatki'!$F5 -> 0 | F5: 40 | H5: 3 | I5: woda | J5: =134+68 -> 202 | N5: Suma | O5: =K43=O3+O4 -> TRUE | P5: =Q5+R5+S5 -> 13849 | Q5: =Q3+Q4 -> 10712 | R5: =R3+R4 -> 2497 | S5: =S3+S4 -> 640
B6: 5 | C6: paliwo | D6: 700 | E6: ='Lipiec25 - wydatki'!$D6-'Lipiec25 - wydatki'!$F6 -> 0.47 | F6: =87.53+300+305+82-75 -> 699.53 | H6: 7 | I6: jedzenie | J6: 800
B7: 6 | C7: jedzenie | D7: 800 | E7: ='Lipiec25 - wydatki'!$D7-'Lipiec25 - wydatki'!$F7 -> 0 | F7: =12.8+105.62+26.22+29.93+2.8+60.78+2.5+12+27.85+111.56+23.42+9.98+52+6+3+136+44.19+174.21+37.94+6.61+9.55-94.96 -> 800 | H7: 9 | I7: smieci | J7: 140 | N7: Oszczędnościowe
B8: 5 | C8: Gaz | D8: 300 | E8: ='Lipiec25 - wydatki'!$D8-F8 -> 0 | F8: =148+152 -> 300 | H8: 10 | I8: izba | J8: 65 | N8: PEKAO | O8: DOM | P8: =4230+261+318-1650+300-223+300-250+250+228 -> 3764 | Q8: po VI
B9: 12 | C9: rozne | D9: 100 | E9: ='Lipiec25 - wydatki'!$D9-'Lipiec25 - wydatki'!$F9 -> 0 | F9: =3.19+40+5+51.81 -> 100 | H9: 11 | I9: lekarz | J9: 300 | O9: NEW CAR | P9: =6660+1230+100+10 -> 8000 | Q9: po VII
B10: 15 | C10: auto | D10: 500 | E10: ='Lipiec25 - wydatki'!$D10-'Lipiec25 - wydatki'!$F10 -> 0 | F10: 500 | H10: 13 | I10: chemia | J10: 50 | O10: GAZ | P10: =127+100+152 -> 379 | Q10: po VII
B11: 17 | C11: fryzjer | D11: 50 | E11: ='Lipiec25 - wydatki'!$D11-'Lipiec25 - wydatki'!$F11 -> 0 | F11: 50 | H11: 14 | I11: mieszkanie | J11: 100 | P11: =P8+P9+P10 -> 12143
B12: 21 | C12: auto new | D12: 1230 | E12: =D12-F12 -> 0 | F12: 1230 | H12: 16 | I12: swieta | J12: 100 | O12: auto | P12: =1510+500+500+500 -> 3010 | Q12: po VII
B13: 22 | C13: Kieszkonkowe D | D13: 650 | E13: ='Lipiec25 - wydatki'!$D13-'Lipiec25 - wydatki'!$F13 -> 0.09 | F13: =100+500+17.91+8+24 -> 649.91 | H13: 18 | I13: fryzjer | J13: 50
C14: RAZEM | D14: =SUM(D4:D13) -> 4455 | E14: =SUM(E4:E13) -> 0.56 | F14: =SUM(F4:F13) -> 4454.44 | H14: 19 | I14: koszty roczne | J14: 350
H15: 20 | I15: konkursy | J15: 50
B16: Koszty dynamiczne Damian | H16: 23 | I16: Kieszkonkowe M | J16: 650
C17: Rodzaj | D17: Budżet | E17: Pozostało | F17: Wydano | I17: RAZEM | J17: =SUM(J4:J16) -> 6257 | K17: =SUM(K4:K16) -> 0 | L17: =SUM(L4:L16) -> 0 | O17: =5310-206+19+83+36 -> 5242 | Q17: =68-52 -> 16
C18: Sanok | D18: 100 | E18: ='Lipiec25 - wydatki'!$D18-F18 -> 0 | F18: 100
C19: Dom | D19: 369 | E19: ='Lipiec25 - wydatki'!$D19-F19 -> 0 | F19: =369 -> 369 | H19: Koszty dynamiczne Malwina
C20: Tv | E20: ='Lipiec25 - wydatki'!$D20-F20 -> 0 | I20: Rodzaj | J20: Budżet | K20: Pozostało | L20: Wydano
C21: RAZEM | D21: =SUM(D18:D20) -> 469 | E21: =SUM(E18:E20) -> 0 | F21: =SUM(F8:F20) -> 7753.35 | H21: 6 | I21: Przedszkole | J21: 1028
H22: 13 | I22: Dzieci | J22: 200
B23: Pozostałe Damian | H23: 14 | I23: Apteka | J23: 100
C24: Rodzaj | D24: Budżet | E24: Pozostało | F24: Wydano | I24: Implant
B25: 8 | C25: Woda | D25: 50 | E25: =D25-F25 -> 0 | F25: =20+20+10 -> 50 | I25: Eris
C26: Szmatki | D26: 69 | E26: =D26-F26 -> 0 | F26: =69 -> 69 | H26: 21 | I26: Wakacje | J26: 400
C27: Youtube | E27: =D27-F27 -> 0 | H27: 25 | I27: Zabawowe | J27: 300
B28: 23 | C28: Prąd | E28: =D28-F28 -> 0 | I28: Kwiaty
C29: Wojtek | E29: =D29-F29 -> 0 | I29: RAZEM | J29: =SUM(J21:J28) -> 2028 | K29: =SUM(K21:K27) -> 0 | L29: =SUM(L21:L27) -> 0
C30: Truskawki
H31: Pozostałe Malwina
I32: Rodzaj | J32: Budżet | K32: Pozostało | L32: Wydano
H33: 22 | I33: Podatek
I34: Ogrody | J34: 168
C35: RAZEM | D35: =SUM(D25:D34) -> 119 | E35: =SUM(E25:E34) -> 0 | F35: =SUM(F25:F30) -> 119 | H35: 20 | I35: Maja lutcza | J35: 50
H36: 24 | I36: urodziny przedsz | J36: 100
C37: pozostało I | D37: =E35+E21+E14 -> 0.56 | E37: 0 | I37: Olini | J37: 83
C38: pozostało XII | H38: 26 | I38: Szczoteczki
C39: Total | E39: =E37+E38+D37 -> 0.56 | I39: ksiazki | J39: 50
I40: Gaja | J40: 70
...

Sheet Kwiecień25 - wydatki 
A1: \
B2: Koszty stałe Damian | H2: Koszty stałe Malwina | N2: Kolumna nr 1 | O2: Wypłaty | P2: Suma | Q2: Koszty stałe | R2: Koszty dyn. | S2: Pozostałe | T2: Podsumowanie
C3: Rodzaj | D3: Budżet | E3: Pozostało | F3: Wydano | I3: Rodzaj | J3: Budżet | K3: Pozostało | L3: Wydano | N3: Damian | O3: =(5186+75+10) -> 5271 | P3: =Q3+R3+S3 -> 4902 | Q3: =D14 -> 4156 | R3: =D21 -> 630 | S3: =D35 -> 116 | T3: =O3-P3 -> 369
B4: 2 | C4: internet | D4: 85 | E4: ='Kwiecień25 - wydatki '!$D4-F4 -> 0 | F4: 85 | H4: 1 | I4: rata | J4: 3105 | N4: Malwina | O4: 7962 | P4: =Q4+R4+S4 -> 8331 | Q4: =J17 -> 5748 | R4: =J29 -> 2084 | S4: =J41 -> 499 | T4: =O4-P4 -> -369
B5: 4 | C5: telefon | D5: 40 | E5: ='Kwiecień25 - wydatki '!$D5-F5 -> 0 | F5: 40 | H5: 3 | I5: woda | J5: 130 | N5: Suma | O5: =K43=O3+O4 -> TRUE | P5: =Q5+R5+S5 -> 13233 | Q5: =Q3+Q4 -> 9904 | R5: =R3+R4 -> 2714 | S5: =S3+S4 -> 615
B6: 5 | C6: paliwo | D6: =800+75 -> 875 | E6: ='Kwiecień25 - wydatki '!$D6-F6 -> 0 | F6: =(300+122+115+133+111+94) -> 875 | H6: 7 | I6: jedzenie | J6: 800
B7: 6 | C7: jedzenie | D7: 900 | E7: ='Kwiecień25 - wydatki '!$D7-F7 -> 0 | F7: =57+31+108+29.92+23.45+10.81+50.1+80.83+184.66+23.94+30.17+10.68+9.78+200.95+31.29+4.5+12.92 -> 900 | H7: 9 | I7: smieci | J7: 128 | N7: Oszczędnościowe
B8: 8 | C8: revolut | D8: 56 | E8: ='Kwiecień25 - wydatki '!$D8-F8 -> 0 | F8: 56 | H8: 10 | I8: izba | J8: 65 | N8: PEKAO | O8: DOM | P8: =4230+261+318-1650+300-223 -> 3236 | Q8: po IV
B9: 12 | C9: rozne | D9: 140 | E9: ='Kwiecień25 - wydatki '!$D9-F9 -> 36 | F9: =(20+40+10+25+9) -> 104 | H9: 11 | I9: lekarz | J9: 300 | O9: NEW CAR | P9: 4660 | Q9: po IV
B10: 15 | C10: auto | D10: 500 | E10: ='Kwiecień25 - wydatki '!$D10-F10 -> 0 | F10: 500 | H10: 13 | I10: chemia | J10: 70 | P10: =P8+P9 -> 7896
B11: 17 | C11: fryzjer | D11: 60 | E11: ='Kwiecień25 - wydatki '!$D11-F11 -> 0 | F11: 60 | H11: 14 | I11: mieszkanie | J11: 100
B12: 21 | C12: auto new | D12: 1000 | E12: ='Kwiecień25 - wydatki '!$D12-F12 -> 0 | F12: 1000 | H12: 16 | I12: swieta | J12: 100 | O12: auto | P12: 1510
B13: 22 | C13: Kieszkonkowe D | D13: 500 | E13: ='Kwiecień25 - wydatki '!$D13-F13 -> 0 | F13: 500 | H13: 18 | I13: fryzjer | J13: 50
C14: RAZEM | D14: =SUM(D4:D13) -> 4156 | E14: =SUM(E4:E13) -> 36 | F14: =SUM(F4:F13) -> 4120 | H14: 19 | I14: koszty roczne | J14: 350
H15: 20 | I15: konkursy | J15: 50
B16: Koszty dynamiczne Damian | H16: 23 | I16: Kieszkonkowe M | J16: 500
C17: Rodzaj | D17: Budżet | E17: Pozostało | F17: Wydano | I17: RAZEM | J17: =SUM(J4:J16) -> 5748 | K17: =SUM(K4:K16) -> 0 | L17: =SUM(L4:L16) -> 0
B18: 5 | C18: Gaz | D18: 330 | E18: =D18-F18 -> 83 | F18: 247
C19: Dom | D19: 300 | E19: =D19-F19 -> 0 | F19: 300 | H19: Koszty dynamiczne Malwina
C20: Tv | E20: =D20-F20 -> 0 | I20: Rodzaj | J20: Budżet | K20: Pozostało | L20: Wydano
C21: RAZEM | D21: =SUM(D18:D20) -> 630 | E21: =SUM(E18:E20) -> 83 | F21: =SUM(F18:F20) -> 547 | H21: 6 | I21: Przedszkole | J21: 1071
H22: 13 | I22: Dzieci | J22: 200 | O22: =88.11+200+84 -> 372.11
B23: Pozostałe Damian | H23: 14 | I23: Apteka | J23: 113
C24: Rodzaj | D24: Budżet | E24: Pozostało | F24: Wydano | I24: Implant | O24: DODAC 94,37
B25: 8 | C25: Woda | D25: 50 | E25: =D25-F25 -> 19 | F25: =16+15 -> 31 | I25: Eris
C26: Zaległości | D26: 0 | E26: =D26-F26 -> 0 | H26: 21 | I26: Wakacje | J26: 400
C27: Youtube | D27: 17 | E27: =D27-F27 -> 0 | F27: 17 | H27: 25 | I27: Zabawowe | J27: 300
B28: 23 | C28: Prąd | D28: 0 | E28: =D28-F28 -> 0 | I28: Kwiaty
C29: Wojtek | D29: 0 | E29: =D29-F29 -> 0 | I29: RAZEM | J29: =SUM(J21:J28) -> 2084 | K29: =SUM(K21:K27) -> 0 | L29: =SUM(L21:L27) -> 0
C30: dudek | D30: 49 | E30: =D30-F30 -> 0 | F30: 49
H31: Pozostałe Malwina
I32: Rodzaj | J32: Budżet | K32: Pozostało | L32: Wydano
H33: 22 | I33: Podatek
I34: Dzień dziadków
C35: RAZEM | D35: =SUM(D25:D34) -> 116 | E35: =SUM(E25:E34) -> 19 | F35: =SUM(F25:F30) -> 97 | H35: 20 | I35: Maja lutcza | J35: 50
H36: 24 | I36: Anglia | J36: 300
C37: pozostało I | E37: =E14+E21+E35 -> 138 | I37: wielkanoc | J37: 100
C38: pozostało XII | H38: 26 | I38: Szczoteczki
C39: Total | E39: =E37+E38 -> 138 | I39: ksiazki | J39: 49
I40: Uro Mai
...

Sheet Czerwiec25 - wydatki
A1: \
B2: Koszty stałe Damian | H2: Koszty stałe Malwina | N2: Kolumna nr 1 | O2: Wypłaty | P2: Suma | Q2: Koszty stałe | R2: Koszty dyn. | S2: Pozostałe | T2: Podsumowanie
C3: Rodzaj | D3: Budżet | E3: Pozostało | F3: Wydano | I3: Rodzaj | J3: Budżet | K3: Pozostało | L3: Wydano | N3: Damian | O3: 5300 | P3: =Q3+R3+S3 -> 4639.5 | Q3: =D14 -> 3931 | R3: =D21 -> 608.5 | S3: =D35 -> 100 | T3: =O3-P3 -> 660.5
B4: 2 | C4: internet | D4: 85 | E4: ='Czerwiec25 - wydatki'!$D4-'Czerwiec25 - wydatki'!$F4 -> 0 | F4: 85 | H4: 1 | I4: rata | J4: 3400 | N4: Malwina | O4: 7682 | P4: =Q4+R4+S4 -> 8342.5 | Q4: =J17 -> 6035 | R4: =J29 -> 2127.5 | S4: =J41 -> 180 | T4: =O4-P4 -> -660.5
B5: 4 | C5: telefon | D5: 40 | E5: ='Czerwiec25 - wydatki'!$D5-'Czerwiec25 - wydatki'!$F5 -> 0 | F5: 40 | H5: 3 | I5: woda | J5: 130 | N5: Suma | O5: =K43=O3+O4 -> TRUE | P5: =Q5+R5+S5 -> 12982 | Q5: =Q3+Q4 -> 9966 | R5: =R3+R4 -> 2736 | S5: =S3+S4 -> 280
B6: 5 | C6: paliwo | D6: 800 | E6: ='Czerwiec25 - wydatki'!$D6-'Czerwiec25 - wydatki'!$F6 -> 182.06 | F6: =8+213+280+105+11.94 -> 617.94 | H6: 7 | I6: jedzenie | J6: 800
B7: 6 | C7: jedzenie | D7: 800 | E7: ='Czerwiec25 - wydatki'!$D7-'Czerwiec25 - wydatki'!$F7 -> 0.02 | F7: =16+9+16+20+57.82+93.21+97.12+210+40+21.53+78+26.49+12.81+102 -> 799.98 | H7: 9 | I7: smieci | J7: 140 | N7: Oszczędnościowe
B8: 8 | C8: revolut | D8: 56 | E8: ='Czerwiec25 - wydatki'!$D8-'Czerwiec25 - wydatki'!$F8 -> 0 | F8: =16+20+20 -> 56 | H8: 10 | I8: izba | J8: 65 | N8: PEKAO | O8: DOM | P8: =4230+261+318-1650+300-223+300-250+250+228 -> 3764 | Q8: po VI
B9: 12 | C9: rozne | D9: 100 | E9: ='Czerwiec25 - wydatki'!$D9-'Czerwiec25 - wydatki'!$F9 -> 0.5 | F9: =24+20.5+9+30+10+6 -> 99.5 | H9: 11 | I9: lekarz | J9: 300 | O9: NEW CAR | P9: 6660 | Q9: po VI
B10: 15 | C10: auto | D10: 500 | E10: ='Czerwiec25 - wydatki'!$D10-'Czerwiec25 - wydatki'!$F10 -> 0 | F10: 500 | H10: 13 | I10: chemia | J10: 50 | O10: GAZ | P10: =127+100 -> 227 | Q10: po VI
B11: 17 | C11: fryzjer | D11: 50 | E11: 20 | F11: =80 -> 80 | H11: 14 | I11: mieszkanie | J11: 100 | P11: =P8+P9+P10 -> 10651
B12: 21 | C12: auto new | D12: 1000 | E12: ='Czerwiec25 - wydatki'!$D12-'Czerwiec25 - wydatki'!$F12 -> 0 | F12: 1000 | H12: 16 | I12: swieta | J12: 100 | O12: auto | P12: =1510+500+500 -> 2510 | Q12: po VI
B13: 22 | C13: Kieszkonkowe D | D13: 500 | E13: ='Czerwiec25 - wydatki'!$D13-'Czerwiec25 - wydatki'!$F13 -> 4.8 | F13: =-29+25+109+26+350+10+4.2 -> 495.2 | H13: 18 | I13: fryzjer | J13: 50
C14: RAZEM | D14: =SUM(D4:D13) -> 3931 | E14: =SUM(E4:E13) -> 207.38 | F14: =SUM(F4:F13) -> 3773.62 | H14: 19 | I14: koszty roczne | J14: 350
H15: 20 | I15: konkursy | J15: 50
B16: Koszty dynamiczne Damian | H16: 23 | I16: Kieszkonkowe M | J16: 500
